Workbook

Sheet Balance Sheet
G1: Microsoft Corporation
G2: Balance Sheet ($ in millions)
G3: Source: Company 10-K filings, FY2024-FY2025 (SEC EDGAR); Cash linked from Cash Flow statement
G4: Line Item | H4: FY 2025 | I4: FY 2024
G5: Assets
G6: Current assets:
G7: Cash and cash equivalents | H7: ='Cash Flow'!C43 -> 30242 | I7: ='Cash Flow'!D43 -> 18315
G8: Short-term investments | H8: 64323 | I8: 57228
G9: Total cash, cash equivalents, and short-term investments | H9: =H7+H8 -> 94565 | I9: =I7+I8 -> 75543
G10: Accounts receivable, net | H10: 69905 | I10: 56924
G11: Inventories | H11: 938 | I11: 1246
G12: Other current assets | H12: 25723 | I12: 26021
G13: Total current assets | H13: =SUM(H9:H12) -> 191131 | I13: =SUM(I9:I12) -> 159734
G14: Property and equipment, net | H14: 204966 | I14: 135591
G15: Operating lease right-of-use assets | H15: 24823 | I15: 18961
G16: Equity and other investments | H16: 15405 | I16: 14600
G17: Goodwill | H17: 119509 | I17: 119220
G18: Intangible assets, net | H18: 22604 | I18: 27597
G19: Other long-term assets | H19: 40565 | I19: 36460
G20: Total assets | H20: =H13+SUM(H14:H19) -> 619003 | I20: =I13+SUM(I14:I19) -> 512163
G21: Liabilities and stockholders’ equity
G22: Current liabilities:
G23: Accounts payable | H23: 27724 | I23: 21996
G24: Short-term debt | H24: 0 | I24: 6693
G25: Current portion of long-term debt | H25: 2999 | I25: 2249
G26: Accrued compensation | H26: 13709 | I26: 12564
G27: Short-term income taxes | H27: 7211 | I27: 5017
G28: Short-term unearned revenue | H28: 64555 | I28: 57582
G29: Other current liabilities | H29: 25020 | I29: 19185
G30: Total current liabilities | H30: =SUM(H23:H29) -> 141218 | I30: =SUM(I23:I29) -> 125286
G31: Long-term debt | H31: 40152 | I31: 42688
G32: Long-term income taxes | H32: 25986 | I32: 27931
G33: Long-term unearned revenue | H33: 2710 | I33: 2602
G34: Deferred income taxes | H34: 2835 | I34: 2618
G35: Operating lease liabilities | H35: 17437 | I35: 15497
G36: Other long-term liabilities | H36: 45186 | I36: 27064
G37: Total liabilities | H37: =H30+SUM(H31:H36) -> 275524 | I37: =I30+SUM(I31:I36) -> 243686
G38: Stockholders’ equity:
G39: Common stock and paid-in capital | H39: 109095 | I39: 100923
G40: Retained earnings | H40: 237731 | I40: 173144
...

Sheet Income Statement
D1: Microsoft Corporation
D2: Income Statement ($ in millions, except per share amounts)
D3: Source: Company 10-K filings, FY2023-FY2025 (SEC EDGAR)
D7: Line Item | E7: FY 2025 | F7: FY 2024 | G7: FY 2023
D8: Revenue:
D9: Product | E9: 63946 | F9: 64773 | G9: 64699
D10: Service and other | E10: 217778 | F10: 180349 | G10: 147216
D11: Total revenue | E11: =E9+E10 -> 281724 | F11: =F9+F10 -> 245122 | G11: =G9+G10 -> 211915
D12: Cost of revenue:
D13: Product | E13: 13501 | F13: 15272 | G13: 17804
D14: Service and other | E14: 74330 | F14: 58842 | G14: 48059
D15: Total cost of revenue | E15: =E13+E14 -> 87831 | F15: =F13+F14 -> 74114 | G15: =G13+G14 -> 65863
D16: Gross margin | E16: =E11-E15 -> 193893 | F16: =F11-F15 -> 171008 | G16: =G11-G15 -> 146052
D17: Research and development | E17: 32488 | F17: 29510 | G17: 27195
D18: Sales and marketing | E18: 25654 | F18: 24456 | G18: 22759
D19: General and administrative | E19: 7223 | F19: 7609 | G19: 7575
D20: Operating income | E20: =E16-SUM(E17:E19) -> 128528 | F20: =F16-SUM(F17:F19) -> 109433 | G20: =G16-SUM(G17:G19) -> 88523
D21: Other income (expense), net | E21: -4901 | F21: -1646 | G21: 788
D22: Income before income taxes | E22: =E20+E21 -> 123627 | F22: =F20+F21 -> 107787 | G22: =G20+G21 -> 89311
D23: Provision for income taxes | E23: 21795 | F23: 19651 | G23: 16950
D24: Net income | E24: =E22-E23 -> 101832 | F24: =F22-F23 -> 88136 | G24: =G22-G23 -> 72361
D25: Earnings per share:
D26: Basic | E26: 13.7 | F26: 11.86 | G26: 9.72
D27: Diluted | E27: 13.64 | F27: 11.8 | G27: 9.68
D28: Weighted average shares outstanding:
D29: Basic | E29: 7433 | F29: 7431 | G29: 7446
D30: Diluted | E30: 7465 | F30: 7469 | G30: 7472

Sheet Cash Flow
B1: Microsoft Corporation
B2: Statement of Cash Flows ($ in millions)
B3: Source: Company 10-K filings, FY2023-FY2025 (SEC EDGAR); Net income linked from Income Statement
B4: Line Item | C4: 2025 | D4: 2024 | E4: 2023
B5: Operations
B6: Net income | C6: ='Income Statement'!E24 -> 101832 | D6: ='Income Statement'!F24 -> 88136 | E6: ='Income Statement'!G24 -> 72361
B7: Adjustments to reconcile net income to net cash from operations:
B8: Depreciation, amortization, and other | C8: 34153 | D8: 22287 | E8: 13861
B9: Stock-based compensation expense | C9: 11974 | D9: 10734 | E9: 9611
B10: Net recognized losses on investments and derivatives | C10: 609 | D10: 305 | E10: 196
B11: Deferred income taxes | C11: -7056 | D11: -4738 | E11: -6059
B12: Changes in operating assets and liabilities:
B13: Accounts receivable | C13: -10581 | D13: -7191 | E13: -4087
B14: Inventories | C14: 309 | D14: 1284 | E14: 1242
B15: Other current assets | C15: -3044 | D15: -1648 | E15: -1991
B16: Other long-term assets | C16: -2950 | D16: -6817 | E16: -2833
B17: Accounts payable | C17: 569 | D17: 3545 | E17: -2721
B18: Unearned revenue | C18: 5438 | D18: 5348 | E18: 5535
B19: Income taxes | C19: -38 | D19: 1687 | E19: -358
B20: Other current liabilities | C20: 5922 | D20: 4867 | E20: 2272
B21: Other long-term liabilities | C21: -975 | D21: 749 | E21: 553
B22: Net cash from operations | C22: =SUM(C6:C21) -> 136162 | D22: =SUM(D6:D21) -> 118548 | E22: =SUM(E6:E21) -> 87582
B23: Financing
B24: Proceeds from issuance (repayments) of debt, maturities of 90 days or less, net | C24: -5746 | D24: 5250 | E24: 0
B25: Proceeds from issuance of debt | C25: 0 | D25: 24395 | E25: 0
B26: Repayments of debt | C26: -3216 | D26: -29070 | E26: -2750
B27: Common stock issued | C27: 2056 | D27: 2002 | E27: 1866
B28: Common stock repurchased | C28: -18420 | D28: -17254 | E28: -22245
B29: Common stock cash dividends paid | C29: -24082 | D29: -21771 | E29: -19800
B30: Other, net | C30: -2291 | D30: -1309 | E30: -1006
B31: Net cash used in financing | C31: =SUM(C24:C30) -> -51699 | D31: =SUM(D24:D30) -> -37757 | E31: =SUM(E24:E30) -> -43935
B32: Investing
B33: Additions to property and equipment | C33: -64551 | D33: -44477 | E33: -28107
B34: Acquisition of companies, net of cash acquired and divestitures, and purchases of intangible and other assets | C34: -5978 | D34: -69132 | E34: -1670
B35: Purchases of investments | C35: -29775 | D35: -17732 | E35: -37651
B36: Maturities of investments | C36: 16079 | D36: 24775 | E36: 33510
B37: Sales of investments | C37: 9309 | D37: 10894 | E37: 14354
B38: Other, net | C38: 2317 | D38: -1298 | E38: -3116
B39: Net cash used in investing | C39: =SUM(C33:C38) -> -72599 | D39: =SUM(D33:D38) -> -96970 | E39: =SUM(E33:E38) -> -22680
B40: Effect of foreign exchange rates on cash and cash equivalents | C40: 63 | D40: -210 | E40: -194
...

Sheet Summary & Ratios.
C2: 2025 | D2: 2024
B3: Gross Margin % | C3: ='Income Statement'!E16/'Income Statement'!E11 -> 0.68823742 | D3: ='Income Statement'!F16/'Income Statement'!F11 -> 0.69764444
B5: Opereting Margin % | C5: ='Income Statement'!E20/'Income Statement'!E11 -> 0.45621956 | D5: ='Income Statement'!F20/'Income Statement'!F11 -> 0.446443
B7: Net Profit Margin % | C7: ='Income Statement'!E24/'Income Statement'!E11 -> 0.36146015 | D7: ='Income Statement'!F24/'Income Statement'!F11 -> 0.35955973
B9: Free Cash Flow (M$) | C9: ='Cash Flow'!C22+'Cash Flow'!C33 -> 71611 | D9: ='Cash Flow'!D22+'Cash Flow'!D33 -> 74071
B11: Current Ratio | C11: ='Balance Sheet'!H13/'Balance Sheet'!H30 -> 1.3534464 | D11: ='Balance Sheet'!I13/'Balance Sheet'!I30 -> 1.2749549

Sheet DCF
C1: 2025 | D1: 2024
B3: NOPAT | C3: ='Income Statement'!E20*(1-('Income Statement'!E23/'Income Statement'!E22)) -> 105868.97 | D3: ='Income Statement'!F20*(1-('Income Statement'!F23/'Income Statement'!F22)) -> 89481.912
B5: NWC | C5: =('Balance Sheet'!H10+'Balance Sheet'!H11+'Balance Sheet'!H12)-('Balance Sheet'!H30-'Balance Sheet'!H24-'Balance Sheet'!H25) -> -41653 | D5: =('Balance Sheet'!I10+'Balance Sheet'!I11+'Balance Sheet'!I12)-('Balance Sheet'!I30-'Balance Sheet'!I24-'Balance Sheet'!I25) -> -32153
B7: Change NWC | C7: =C5-D5 -> -9500
B9: UFCF | C9: =C3+'Cash Flow'!C8+'Cash Flow'!C33-C7 -> 84970.971 | D9: =D3+'Cash Flow'!D8+'Cash Flow'!D33-D7 -> 67291.912
B11: Total Debt Bridge Value | C11: ='Balance Sheet'!H24+'Balance Sheet'!H25+'Balance Sheet'!H31 -> 43151 | D11: ='Balance Sheet'!I24+'Balance Sheet'!I25+'Balance Sheet'!I31 -> 51630
B13: WACC | C13: =(0.98 * (0.042 + (0.9 * 0.05))) + (0.02 * (0.04 * (1 - ('Income Statement'!E23 / 'Income Statement'!E22)))) -> 0.085918963 | D13: =(0.98 * (0.042 + (0.9 * 0.05))) + (0.02 * (0.04 * (1 - ('Income Statement'!F23 / 'Income Statement'!F22)))) -> 0.085914149
B15: Terminal Value | C15: =(C9 * 1.03) / (C13 - 0.03) -> 1565123.8 | D15: =(D9 * 1.03) / (D13 - 0.03) -> 1239590.9
B17: Implied Equity | C17: =C15 - C11 + 'Balance Sheet'!H9 -> 1616537.8 | D17: =D15 - D11 + 'Balance Sheet'!I9 -> 1263503.9
B19: Implied Share Price | C19: =C17 / 'Income Statement'!E30 -> 216.54894 | D19: =D17 / 'Income Statement'!F30 -> 169.16641
